<?xml version="1.0" encoding="utf-8"?>
<!-- This URDF was automatically created by SolidWorks to URDF Exporter! Originally created by Stephen Brawner (brawner@gmail.com)
     Commit Version: 1.6.0-4-g7f85cfe  Build Version: 1.6.7995.38578
     For more information, please see http://wiki.ros.org/sw_urdf_exporter -->
<robot
  name="the_bust2_right_arm">
  <link name="world_base"/>
  <joint name="world_shift" type="fixed">
    <origin xyz="0 0 0" rpy="0 0 1.57" />
    <parent link="world_base" />
    <child link="link0" />
    <axis xyz="0 0 1" />
  </joint>
  <link
    name="link0">
    <inertial>
      <origin
        xyz="-0.080255 -0.75157 -0.00014821"
        rpy="0 0 0" />
      <mass
        value="9.7839" />
      <inertia
        ixx="0.20727"
        ixy="-3.2824E-05"
        ixz="-1.1214E-06"
        iyy="0.28988"
        iyz="-9.4868E-05"
        izz="0.29461" />
    </inertial>
    <visual>
      <origin
        xyz="0 0 0"
        rpy="0 0 0" />
      <geometry>
        <mesh
          filename="../assets/the_bust2/BODY_with_cover.obj" />
      </geometry>
      <material
        name="">
        <color
          rgba="0.79216 0.81961 0.93333 1" />
      </material>
    </visual>
    <collision>
      <origin
        xyz="0 0 0"
        rpy="0 0 0" />
      <geometry>
        <mesh
          filename="../assets/the_bust2/BODY_with_cover.obj" />
      </geometry>
    </collision>
  </link>

  <joint name="joint0_pillar" type="fixed">
    <origin xyz="0 0 0" rpy="0 0 0" />
    <parent link="link0" />
    <child link="link0_pillar" />
    <axis xyz="0 0 1" />
  </joint>
  <link
    name="link0_pillar">
    <inertial>
      <origin
        xyz="0 0 0"
        rpy="0 0 0" />
      <mass
        value="9.7839" />
      <inertia
        ixx="0.20727"
        ixy="-3.2824E-05"
        ixz="-1.1214E-06"
        iyy="0.28988"
        iyz="-9.4868E-05"
        izz="0.29461" />
    </inertial>
    <visual>
      <origin
        xyz="0 0 0"
        rpy="0 0 0" />
      <geometry>
        <mesh
          filename="../assets/the_bust2/BODY_PILLAR_with_cover.obj" />
      </geometry>
      <material
        name="">
        <color
          rgba="0.79216 0.81961 0.93333 1" />
      </material>
    </visual>
    <collision>
      <origin
        xyz="0 0 0"
        rpy="0 0 0" />
      <geometry>
        <mesh
          filename="../assets/the_bust2/BODY_PILLAR_with_cover.obj" />
      </geometry>
    </collision>
  </link>

  <link
    name="link1">
    <inertial>
      <origin
        xyz="-0.058646 0.010623 -0.0013946"
        rpy="0 0 0" />
      <mass
        value="0.90109" />
      <inertia
        ixx="0.00071734"
        ixy="-4.067E-06"
        ixz="-2.2324E-06"
        iyy="0.00071668"
        iyz="3.4643E-07"
        izz="0.00099893" />
    </inertial>
    <visual>
      <origin
        xyz="0 0 0"
        rpy="0 0 0" />
      <geometry>
        <mesh
          filename="../assets/the_bust2/SHOULDER_1_with_cover.obj" />
      </geometry>
      <material
        name="">
        <color
          rgba="0.79216 0.81961 0.93333 1" />
      </material>
    </visual>
    <collision>
      <origin
        xyz="0 0 0"
        rpy="0 0 0" />
      <geometry>
        <mesh
          filename="../assets/the_bust2/SHOULDER_1_with_cover.obj" />
      </geometry>
    </collision>
  </link>
  <joint
    name="joint1"
    type="revolute">
    <origin
      xyz="-0.14964 0 0.060725"
      rpy="1.5708 0 0" />
    <parent
      link="link0" />
    <child
      link="link1" />
    <axis
      xyz="-0.98481 0.17365 0" />
    <limit effort="87" lower="-3.142" upper="3.142" velocity="2.0"/>
  </joint>
  <link
    name="link2">
    <inertial>
      <origin
        xyz="-0.00535772591526545 -0.0793139517046481 -9.23922563859696E-06"
        rpy="0 0 0" />
      <mass
        value="0.649472174212296" />
      <inertia
        ixx="0.000372167174448577"
        ixy="-5.67559650733523E-07"
        ixz="1.11598896451532E-07"
        iyy="0.000429826310385547"
        iyz="4.2959102078216E-07"
        izz="0.000400174040241547" />
    </inertial>
    <visual>
      <origin
        xyz="0 0 0"
        rpy="0 0 0" />
      <geometry>
        <mesh
          filename="../assets/the_bust2/SHOULDER_2_with_cover.obj" />
      </geometry>
      <material
        name="">
        <color
          rgba="0.792156862745098 0.819607843137255 0.933333333333333 1" />
      </material>
    </visual>
    <collision>
      <origin
        xyz="0 0 0"
        rpy="0 0 0" />
      <geometry>
        <mesh
          filename="../assets/the_bust2/SHOULDER_2_with_cover.obj" />
      </geometry>
    </collision>
  </link>
  <joint
    name="joint2"
    type="revolute">
    <origin
      xyz="-0.060083 0.010594 0"
      rpy="0 0 0" />
    <parent
      link="link1" />
    <child
      link="link2" />
    <axis
      xyz="0 0 -1" />
    <limit effort="87" lower="-0.1" upper="3.142" velocity="2.0"/>
  </joint>
  <link
    name="link3">
    <inertial>
      <origin
        xyz="-0.000355282485146768 -0.00124933319201412 -0.0762484667452232"
        rpy="0 0 0" />
      <mass
        value="0.098196868702324" />
      <inertia
        ixx="0.000130311751597374"
        ixy="-4.63732473212988E-07"
        ixz="4.14973236884063E-07"
        iyy="0.000122852441640541"
        iyz="6.68222480742808E-06"
        izz="5.20498909664746E-05" />
    </inertial>
    <visual>
      <origin
        xyz="0 0 0"
        rpy="0 0 0" />
      <geometry>
        <mesh
          filename="../assets/the_bust2/ARM_1_with_cover.obj" />
      </geometry>
      <material
        name="">
        <color
          rgba="0.866666666666667 0.866666666666667 0.890196078431372 1" />
      </material>
    </visual>
    <collision>
      <origin
        xyz="0 0 0"
        rpy="0 0 0" />
      <geometry>
        <mesh
          filename="../assets/the_bust2/ARM_1_with_cover.obj" />
      </geometry>
    </collision>
  </link>
  <joint
    name="joint3"
    type="revolute">
    <origin
      xyz="-0.0055 -0.113 0"
      rpy="1.5708 -0.062021 3.1416" />
    <parent
      link="link2" />
    <child
      link="link3" />
    <axis
      xyz="0 0 -1" />
    <limit effort="87" lower="-3.142" upper="3.142" velocity="2.0"/>
  </joint>
  <link
    name="link4">
    <inertial>
      <origin
        xyz="0.000320113590613069 -0.0582629274686154 0.000795425891252129"
        rpy="0 0 0" />
      <mass
        value="0.0953973399101085" />
      <inertia
        ixx="6.58987096231067E-05"
        ixy="2.45738434072835E-09"
        ixz="4.68028555793376E-08"
        iyy="6.82790255692881E-05"
        iyz="-4.44343875203888E-07"
        izz="5.77673345660481E-05" />
    </inertial>
    <visual>
      <origin
        xyz="0 0 0"
        rpy="0 0 0" />
      <geometry>
        <mesh
          filename="../assets/the_bust2/ARM_2_with_cover.obj" />
      </geometry>
      <material
        name="">
        <color
          rgba="0.792156862745098 0.819607843137255 0.933333333333333 1" />
      </material>
    </visual>
    <collision>
      <origin
        xyz="0 0 0"
        rpy="0 0 0" />
      <geometry>
        <mesh
          filename="../assets/the_bust2/ARM_2_with_cover.obj" />
      </geometry>
    </collision>
  </link>
  <joint
    name="joint4"
    type="revolute">
    <origin
      xyz="0 0 -0.1465"
      rpy="1.5708 0 3.0796" />
    <parent
      link="link3" />
    <child
      link="link4" />
    <axis
      xyz="-1 0 0" />
    <limit effort="87" lower="-0.01" upper="2.0944" velocity="2.0"/>
  </joint>
  <link
    name="link5">
    <inertial>
      <origin
        xyz="0.000493375711402677 -0.000130653778922423 0.046579179371954"
        rpy="0 0 0" />
      <mass
        value="0.217814758640261" />
      <inertia
        ixx="0.00028119739542552"
        ixy="-1.32568846933065E-05"
        ixz="1.36805191466711E-06"
        iyy="0.000284643745428063"
        iyz="7.34861520892946E-07"
        izz="0.000117915595371944" />
    </inertial>
    <visual>
      <origin
        xyz="0 0 0"
        rpy="0 0 0" />
      <geometry>
        <mesh
          filename="../assets/the_bust2/FOREARM_1_with_cover.obj" />
      </geometry>
      <material
        name="">
        <color
          rgba="0.898039215686275 0.917647058823529 0.929411764705882 1" />
      </material>
    </visual>
    <collision>
      <origin
        xyz="0 0 0"
        rpy="0 0 0" />
      <geometry>
        <mesh
          filename="../assets/the_bust2/FOREARM_1_with_cover.obj" />
      </geometry>
    </collision>
  </link>
  <joint
    name="joint5"
    type="revolute">
    <origin
      xyz="0 -0.0945 0"
      rpy="1.5708 0 0" />
    <parent
      link="link4" />
    <child
      link="link5" />
    <axis
      xyz="0 0 1" />
    <limit effort="87" lower="-3.142" upper="3.142" velocity="2.0"/>
  </joint>
  <link
    name="link6">
    <inertial>
      <origin
        xyz="2.5011749909265E-06 6.98671781989973E-06 0.0108566208822707"
        rpy="0 0 0" />
      <mass
        value="0.0851084608381543" />
      <inertia
        ixx="6.52848876662652E-05"
        ixy="6.880334348113E-06"
        ixz="2.94099464720527E-09"
        iyy="4.40039650720911E-05"
        iyz="-6.6266349783088E-09"
        izz="5.02184199911762E-05" />
    </inertial>
    <visual>
      <origin
        xyz="0 0 0"
        rpy="0 0 0" />
      <geometry>
        <mesh
          filename="../assets/the_bust2/WRIST_1_with_cover.obj" />
      </geometry>
      <material
        name="">
        <color
          rgba="0.898039215686275 0.917647058823529 0.929411764705882 1" />
      </material>
    </visual>
    <collision>
      <origin
        xyz="0 0 0"
        rpy="0 0 0" />
      <geometry>
        <mesh
          filename="../assets/the_bust2/WRIST_1_with_cover.obj" />
      </geometry>
    </collision>
  </link>
  <joint
    name="joint6"
    type="revolute">
    <origin
      xyz="0 0 0.122"
      rpy="0 0 3.1416" />
    <parent
      link="link5" />
    <child
      link="link6" />
    <axis
      xyz="0 1 0" />
    <limit effort="87" lower="-1.57" upper="1.57" velocity="2.0"/>
  </joint>
  <link
    name="link7">
    <inertial>
      <origin
        xyz="1.73301732420139E-06 -4.1365530679765E-05 0.0148102063345591"
        rpy="0 0 0" />
      <mass
        value="0.0428723129385903" />
      <inertia
        ixx="9.75704695559401E-06"
        ixy="7.63671624727678E-07"
        ixz="1.15801307311595E-09"
        iyy="1.5033546521057E-05"
        iyz="2.53058408504609E-08"
        izz="1.75356539058599E-05" />
    </inertial>
    <visual>
      <origin
        xyz="0 0 0"
        rpy="0 0 0" />
      <geometry>
        <mesh
          filename="../assets/the_bust2/WRIST_2_with_cover.obj" />
      </geometry>
      <material
        name="">
        <color
          rgba="0.898039215686275 0.917647058823529 0.929411764705882 1" />
      </material>
    </visual>
    <collision>
      <origin
        xyz="0 0 0"
        rpy="0 0 0" />
      <geometry>
        <mesh
          filename="../assets/the_bust2/WRIST_2_with_cover.obj" />
      </geometry>
    </collision>
  </link>
  <joint
    name="joint7"
    type="revolute">
    <origin
      xyz="0 0 0.04"
      rpy="0 0 3.1416" />
    <parent
      link="link6" />
    <child
      link="link7" />
    <axis
      xyz="-1 0 0" />
    <limit effort="87" lower="-1.57" upper="1.57" velocity="2.0"/>
  </joint>

  <!-- hand mount -->
  <joint
    name="hand_mount_joint"
    type="fixed">
    <origin
      xyz="0 0 0.03"
      rpy="0 0 0" />
    <parent
      link="link7" />
    <child
      link="hand_mount_link" />
    <axis
      xyz="1 0 0" />
  </joint>
  <link name="hand_mount_link"/>

  <!-- camera -->
  <joint name="camera_joint" type="fixed">
    <parent link="link0"/>
    <child link="camera_rgb"/>
    <origin rpy="-2.667044 0.097502 3.099910" xyz="-0.001564 -0.105504 0.182075"/>
  </joint>
  <link name="camera_rgb"/>

  <joint name="rgb_to_center" type="fixed">
    <parent link="camera_rgb" />
    <child link="camera_center" />
    <origin xyz="-0.0115 0 0" rpy="0 0 0" />
  </joint>
  <link name="camera_center" />

  <joint name="camera_center_to_mesh" type ="fixed">
    <parent link="camera_center" />
    <child link="camer_mesh" />
    <origin xyz="0 0 0" rpy="0 0 3.141592" />
  </joint>
  <link
      name="camer_mesh">
      <visual>
      <origin
          xyz="0 0 0"
          rpy="0 0 0" />
      <geometry>
          <mesh
          filename="../assets/object/collision/d455.obj" scale="0.001 0.001 0.001"/>
      </geometry>
      <material
          name="">
          <color
          rgba="1 1 1 1" />
      </material>
      </visual>
      <collision>
      <origin
          xyz="0 0 0"
          rpy="0 0 0" />
      <geometry>
          <mesh
          filename="../assets/object/collision/d455.obj"  scale="0.001 0.001 0.001"/>
      </geometry>
      </collision>
  </link>

  <!-- calibrator panel -->
  <joint
    name="panel_joint"
    type="fixed">
    <origin
      xyz="0 0 0.16"
      rpy="0 0 0" />
    <parent
      link="hand_mount_link" />
    <child
      link="panel" />
    <axis
      xyz="1 0 0" />
  </joint>
  <link name="panel">
    <visual>
      <origin
        xyz="0 0 0"
        rpy="0 0 0" />
      <geometry>
        <box size="0.21 0.05 0.32"/>
      </geometry>
      <material
        name="">
        <color
          rgba="0.8 0.8 0.8 1.0" />
      </material>
    </visual>
    <collision>
      <origin
        xyz="0 0 0"
        rpy="0 0 0" />
      <geometry>
        <box size="0.21 0.05 0.32"/>
      </geometry>
    </collision>
  </link>
</robot>
